segments_over_time_plot_2019.html
segments_over_time_this_year_plot_2019.html
stacked_plot_2019.html
Traceback (most recent call last):
  File "/usr/local/lib/python3.4/dist-packages/pandas/core/indexes/base.py", line 2525, in get_loc
    return self._engine.get_loc(key)
  File "pandas/_libs/index.pyx", line 117, in pandas._libs.index.IndexEngine.get_loc
  File "pandas/_libs/index.pyx", line 139, in pandas._libs.index.IndexEngine.get_loc
  File "pandas/_libs/hashtable_class_helper.pxi", line 1265, in pandas._libs.hashtable.PyObjectHashTable.get_item
  File "pandas/_libs/hashtable_class_helper.pxi", line 1273, in pandas._libs.hashtable.PyObjectHashTable.get_item
KeyError: 'name'

During handling of the above exception, another exception occurred:

Traceback (most recent call last):
  File "segment_plots.py", line 138, in <module>
    Scatter_Plot2(df_distance,'name','datetime','distance','lines','Distance(km)','','distance')
  File "segment_plots.py", line 9, in Scatter_Plot2
    cat_list = df[colour].unique()
  File "/usr/local/lib/python3.4/dist-packages/pandas/core/frame.py", line 2139, in __getitem__
    return self._getitem_column(key)
  File "/usr/local/lib/python3.4/dist-packages/pandas/core/frame.py", line 2146, in _getitem_column
    return self._get_item_cache(key)
  File "/usr/local/lib/python3.4/dist-packages/pandas/core/generic.py", line 1842, in _get_item_cache
    values = self._data.get(item)
  File "/usr/local/lib/python3.4/dist-packages/pandas/core/internals.py", line 3843, in get
    loc = self.items.get_loc(item)
  File "/usr/local/lib/python3.4/dist-packages/pandas/core/indexes/base.py", line 2527, in get_loc
    return self._engine.get_loc(self._maybe_cast_indexer(key))
  File "pandas/_libs/index.pyx", line 117, in pandas._libs.index.IndexEngine.get_loc
  File "pandas/_libs/index.pyx", line 139, in pandas._libs.index.IndexEngine.get_loc
  File "pandas/_libs/hashtable_class_helper.pxi", line 1265, in pandas._libs.hashtable.PyObjectHashTable.get_item
  File "pandas/_libs/hashtable_class_helper.pxi", line 1273, in pandas._libs.hashtable.PyObjectHashTable.get_item
KeyError: 'name'
